-----
Filename: /home/xuanfeng/UB-bug-research/datasets/Juliet-C-C-1.3/testcases/linux/analysis/previous/old-prompt/temp-1/part_5/extr_membarrier_test_impl.h_test_membarrier_register_private_expedited_sync_core_success.c  
UB Detected: Yes  
UB Reason: The `sys_membarrier` function is called without verifying its success status properly. If `sys_membarrier(cmd, flags)` fails (returns non-zero), it leads to a possible misinterpretation of the return value since the function doesn't define any behavior directly for failure cases beyond returning non-zero from `sys_membarrier`. It could potentially dereference or interact with undefined states caused by `errno`, which might not always be meaningful in certain runtime environments.  
  
Bug Detected: Yes  
Bug Type: Logic Flaw, Error Handling  
Bug Reason: If `sys_membarrier(cmd, flags)` fails, the test is marked as failed (`ksft_exit_fail_msg`), but no cleanup or error recovery is performed. Furthermore, there is no explicit handling of the reason why the registration failed. This results in a lack of graceful degradation or recovery of the test process, potentially leading to a premature exit of the test suite.  

Bug Caused by UB: No  
Confidence: High  
Fix Suggestion: Revise the error handling for `sys_membarrier` failure cases. Add safeguards to confirm the proper setting and meaning of `errno`, and introduce context-aware error handling to provide more useful diagnostic information. For example:  
```c  
if (sys_membarrier(cmd, flags) != 0) {  
    if (errno == EINVAL) {  
        ksft_exit_fail_msg("Command not supported: %s, flags = %d, errno = %d\n", test_name, flags, errno);  
    } else {  
        ksft_exit_fail_msg("System call failed: %s, flags = %d, errno = %d\n", test_name, flags, errno);  
    }  
}
```  
-----

